Workbook

Sheet VCU calculation
B3: CPA1 - Man and Man Enterprise Improved Cooking Stoves Programme in Ghana (Brong-Ahafo region) | F3: AMS-II.G Version 08.0
A6: Montoring period of CPA001 | C6: 44713 | D6: 44926
E8: Value for CPA1 (VCS) | F8: Unit
B9: Micro-scale energy savings limit | E9: 1800 | F9: MWhth/app/y
B10: Energy savings per stove | E10: =E11*E17*E23 -> 7.0169492 | F10: MWhth/y
B11: NCV biomass (charcoal) | E11: =E12*1000/3.6 -> 4.1666667 | F11: MWhth/t
B12: NCVbiomass | E12: 0.015 | F12: TJ/ton
B13: fNRB,y | E13: 0.9884 | F13: %
B14: EFprojected_fossilfuel | E14: 81.6 | F14: tCO2/TJ
B15: ηold,i,j | E15: 0.18 | F15: %
B16: ηnew,i,i | E16: 0.295 | F16: %
B17: Energy savings | E17: =1-(E15/E16) -> 0.38983051 | F17: %
B18: Stoves under CPA | E18: ='Database - main figures'!B8 -> 203460 | F18: units
B19: Historical biomass consumption per capita per year | E19: 180 | F19: kg/pers/year
B20: Mwood to charcoal factor | E20: 6 | F20: kg of wood for 1 kg of charcoal
B21: Bold,p | E21: =E19*E20/1000 -> 1.08 | F21: tonnes of wood equivalent/capita/y
B22: Np/HH | E22: 4 | F22: person / household
B23: Bold,HH = Bold,p * Np/HH | E23: =E22*E21 -> 4.32 | F23: tonnes/household/year
B24: Leakageadj | E24: 0.95 | F24: fraction
B25: By,savings,i,j = Bold,i,j * (1 - ηold,i,j/ηnew,i,j)*Leakageadj | E25: =E23*(1-E15/E16)*E24 -> 1.5998644 | F25: tons
B26: pop_stoves,y | E26: ='MP5 Monitoring surveys'!J213 -> 0.93809524 | F26: %
B27: Ny,i,j = Number of stoves * pop_stoves,y | E27: =O51+O58+O44 -> 192281.82 | F27: units
B28: µ,y (pre-project devices use) | E28: ='MP5 Monitoring surveys'!P213 -> 0.13951262 | F28: %
B29: Crediting period Monitoring Report | E29: =D6-C6+1 -> 214 | F29: days
B30: yellow = monitored parameter
B32: Emission reductions
F34: By,savings,i,j = Bold,i,j * (1 - ηold,i,j/ηnew,i,j)*Leakageadj
B37: Baseline emission = Bold,i,j* Fnrb* NCVbiomass *Efprojected_fossilfuel *Ny,I*U,y*Year prorata
B38: Project emission = (Bold,i,j- Bysaving)* Fnrb* NCVbiomass *Efprojected_fossilfuel *Ny,I*U,y*Year prorata
B39: Leakage = 0.95 factor applied to By,savings,i,j
B40: Emissions reductions = Baselines emissions - Project emissions - Leakages emissions
C41: 2018
C42: ERy | D42: ERs Ecoeye | E42: ERs KZ | F42: fNRB,y | G42: NCVbiomass | H42: EFprojected_fossilfuel | I42: By,savings | J42: ηold | K42: ηnew,y | L42: Nd,HH | M42: Bold,i,j | N42: Leakageadj | O42: Ny,i,j | P42: Poperational | Q42: Bold,HH | R42: 1- µ,y
C43: tCO2e | D43: tCO2e | E43: tCO2e | F43: % | G43: TJ/ton | H43: tCO2/TJ | I43: tons | J43: % | K43: % | L43: number | M43: tons | N43: fraction | O43: quantity | P43: % | Q43: tons/stove/y | R43: fraction
B44: 01/06/2022 - 31/12/2022 | C44: =(D44+E44) -> 29226 | D44: =ROUNDUP(F44*G44*(E29/365)*H44*I44*(13000*P44)*R44,0) -> 10812 | E44: =ROUNDDOWN(F44*G44*(E29/365)*H44*I44*(O44-13000*P44)*R44,0) -> 18414 | F44: =E13 -> 0.9884 | G44: =E12 -> 0.015 | H44: =E14 -> 81.6 | I44: =M44*(1-J44/K44)*N44 -> 1.5312988 | J44: =$E$15 -> 0.18 | K44: 0.295 | L44: ='MP5 Monitoring surveys'!H228 -> 1.0447761 | M44: =Q44/L44 -> 4.1348571 | N44: 0.95 | O44: ='Database - main figures'!D18*P44 -> 32519.463 | P44: ='MP5 Monitoring surveys'!I229 -> 0.92537313 | Q44: =E23 -> 4.32 | R44: =1-'MP5 Monitoring surveys'!M229 -> 0.82744841
B45: TOTAL | C45: =C44 -> 29226 | F45: - | G45: - | H45: - | J45: - | K45: - | M45: - | N45: - | O45: - | Q45: -
C48: 2019
C49: ERy | D49: ERs Ecoeye | E49: ERs KZ | F49: fNRB,y | G49: NCVbiomass | H49: EFprojected_fossilfuel | I49: By,savings | J49: ηold | K49: ηnew,y | L49: Nd,HH | M49: Bold,i,j | N49: Leakageadj | O49: Ny,i,j | P49: Poperational | Q49: Bold,HH | R49: 1- µ,y
C50: tCO2e | D50: tCO2e | E50: tCO2e | F50: % | G50: TJ/ton | H50: tCO2/TJ | I50: tons | J50: % | K50: % | L50: number | M50: tons | N50: fraction | O50: quantity | P50: % | Q50: tons/stove/y | R50: fraction
B51: 01/06/2022 - 31/12/2022 | C51: =(D51+E51) -> 58572 | D51: =ROUNDDOWN(F51*G51*(E29/365)*H51*I51*0*R51,0) -> 0 | E51: =ROUNDDOWN(F51*G51*(E29/365)*H51*I51*O51*R51,0) -> 58572 | F51: =E13 -> 0.9884 | G51: =E12 -> 0.015 | H51: =E14 -> 81.6 | I51: =M51*(1-J51/K51)*N51 -> 1.4529703 | J51: =$E$15 -> 0.18 | K51: ='MP5 stoves efficiency '!F7 -> 0.29411111 | L51: ='MP5 Monitoring surveys'!H241 -> 1.0958904 | M51: =Q51/L51 -> 3.942 | N51: 0.95 | O51: ='Database - main figures'!D19*P51 -> 64129.096 | P51: ='MP5 Monitoring surveys'!I242 -> 0.91780822 | Q51: =E23 -> 4.32 | R51: =1-'MP5 Monitoring surveys'!M242 -> 0.88623031
...

Sheet Tableau suivi ECOEYE
B6: Man and Man Enterprise Improved Cooking Stoves CDM Programme in Ghana support by Republic of Korea | J6: AMS-II.G Version 08.0
F11: Value | G11: Unit | H11: Source
B12: Small-scale CPA energy savings limit | F12: 180 | G12: GWhth/y | H12: CDM Project Standard
B13: Energy savings per stove | F13: =F14*F18*F23 -> 6.2181818 | G13: MWhth/y | H13: Calculated
B14: NCVbiomass | F14: =15/3.6 -> 4.1666667 | G14: MWhth/t | H14: IPCC (2006) (default value for wood fuel: 0.015 TJ/tonne)
B15: ηold,i,j | F15: 0.18 | G15: % | H15: Hedon (2012): https://bit.ly/2PRs47H, also mentioned in Ghana case study – Growing Inclusive Markets (UNDP, 2010) : https://bit.ly/2R8pYAs
B16: ηnew,i,i | F16: =J42 -> 0.275 | G16: % | H16: Internal assumption for ex-ante purposes
B17: Decrease in initial efficiency | F17: 0.01 | G17: per year | H17: Assumption for ex-ante purposes only
B18: Energy savings | F18: =1-(F15/F16) -> 0.34545455 | G18: % | H18: Calculated
B19: mwood / mcharcoal factor | F19: 6 | G19: kg of wood for 1 kg of charcoal | H19: AMS II.G.
B20: Bold,HH = Bold,p * Np,HH
B21: Bold,p | F21: =180 -> 180 | G21: kg/HH/year | H21: FAO 2017
B22: Np,HH | F22: 4 | G22: HH | H22: Ghana Statistical Service 2014
B23: Bold,HH | F23: =F21*F22*F19/1000 -> 4.32 | G23: tonnes/year | H23: Calculated
B24: Bold,i,j = Bold,HH / Nd,HH
B25: Nd,hh (number of stoves per household) | F25: 1 | H25: Internal assumption for ex-ante purposes
B26: Bold,l,j | F26: =F23/F25 -> 4.32 | G26: tonnes/year | H26: Calculated
B27: pop_stoves,y | F27: 0.9448 | G27: % | H27: Internal assumption for ex-ante purposes
B28: µy (pre-project devices use) | F28: =0.878 -> 0.878 | G28: % | H28: Internal assumption for ex-ante purposes
B29: yellow = monitored parameter
B32: Emission reductions (per stove)
H34: leakage considered | I34: By,savings,i,j = Bold,i,j * (1 - ηold,i,j/ηnew,i,j)
C35: ERy | D35: fNRB,y | E35: NCVbiomass | F35: EFprojected_fossilfuel | G35: By,savings | H35: By,savings | I35: ηold | J35: ηnew,y | K35: Bold,i,j | L35: Leakageadj | M35: Ny,i | N35: µy | O35: pop_stoves,y | P35: Nd,HH | Q35: Bold,HH
C36: tCO2e | D36: % | E36: TJ/ton | F36: tCO2/TJ | G36: tons | H36: tons | I36: % | J36: % | K36: tons | L36: fraction | M36: quantity | N36: % | P36: quantity | Q36: tonnes/year
B37: typical 1st year | C37: 1.6056048 | D37: 0.98841577 | E37: 0.015 | F37: 81.6 | G37: 1.5998644 | H37: 1.6840678 | I37: 0.18 | J37: 0.295 | K37: 4.32 | L37: 0.95 | M37: 0.9448 | N37: 0.878 | O37: 0.9448 | P37: 1 | Q37: 4.32
B38: typical 2nd year | C38: 1.5174251 | D38: 0.98841577 | E38: 0.015 | F38: 81.6 | G38: 1.512 | H38: 1.5915789 | I38: 0.18 | J38: 0.285 | K38: 4.32 | L38: 0.95 | M38: 0.9448 | N38: 0.878 | O38: 0.9448 | P38: 1 | Q38: 4.32
B39: typical 3rd year | C39: 1.4228324 | D39: 0.98841577 | E39: 0.015 | F39: 81.6 | G39: 1.4177455 | H39: 1.4923636 | I39: 0.18 | J39: 0.275 | K39: 4.32 | L39: 0.95 | M39: 0.9448 | N39: 0.878 | O39: 0.9448 | P39: 1 | Q39: 4.32
B40: typical 4th year | C40: 0.90888589 | D40: 0.98841577 | E40: 0.015 | F40: 81.6 | G40: 1.3163774 | H40: 1.3856604 | I40: 0.18 | J40: 0.265 | K40: 4.32 | L40: 0.95 | M40: 0.65 | N40: 0.878 | O40: 0.65 | P40: 1 | Q40: 4.32
B41: typical 5th year | C41: 0.5769744 | D41: 0.98841577 | E41: 0.015 | F41: 81.6 | G41: 1.2070588 | H41: 1.2705882 | I41: 0.18 | J41: 0.255 | K41: 4.32 | L41: 0.95 | M41: 0.45 | N41: 0.878 | O41: 0.45 | P41: 1 | Q41: 4.32
B42: average values: | C42: =AVERAGE(C37:C41) -> 1.2063445 | G42: =AVERAGE(G37:G41) -> 1.4106092 | H42: =AVERAGE(H37:H41) -> 1.4848518 | J42: =AVERAGE(J37:J41) -> 0.275 | M42: =AVERAGE(M37:M41) -> 0.78688 | O42: =AVERAGE(O37:O41) -> 0.78688
B44: CPA1-MP1 | C44: 1.0347968 | D44: 0.9884 | E44: 0.015 | F44: 81.6 | G44: 1.0145924 | I44: 0.18 | J44: 0.24058677 | K44: 4.2409383 | L44: 0.95 | M44: 0.98148148 | N44: 0.85894863 | O44: 0.98148148 | P44: 1.0186425 | Q44: 4.32
B45: CPA1-MP2 | C45: ='VCU calculation'!#REF! -> #REF! | D45: ='VCU calculation'!#REF! -> #REF! | E45: ='VCU calculation'!#REF! -> #REF! | F45: ='VCU calculation'!#REF! -> #REF! | G45: ='VCU calculation'!#REF! -> #REF! | I45: ='VCU calculation'!#REF! -> #REF! | J45: ='VCU calculation'!#REF! -> #REF! | K45: ='VCU calculation'!#REF! -> #REF! | L45: ='VCU calculation'!#REF! -> #REF! | M45: ='VCU calculation'!#REF! -> #REF! | N45: ='VCU calculation'!#REF! -> #REF! | O45: ='VCU calculation'!#REF! -> #REF! | P45: ='VCU calculation'!#REF! -> #REF! | Q45: ='VCU calculation'!#REF! -> #REF!
B46: CPA2-MP2 | C46: ='VCU calculation'!#REF! -> #REF! | D46: ='VCU calculation'!#REF! -> #REF! | E46: ='VCU calculation'!#REF! -> #REF! | F46: ='VCU calculation'!#REF! -> #REF! | G46: ='VCU calculation'!#REF! -> #REF! | I46: ='VCU calculation'!#REF! -> #REF! | J46: ='VCU calculation'!#REF! -> #REF! | K46: ='VCU calculation'!#REF! -> #REF! | L46: ='VCU calculation'!#REF! -> #REF! | M46: ='VCU calculation'!#REF! -> #REF! | N46: ='VCU calculation'!#REF! -> #REF! | O46: ='VCU calculation'!#REF! -> #REF! | P46: ='VCU calculation'!#REF! -> #REF! | Q46: ='VCU calculation'!#REF! -> #REF!
C49: 2018 (>12/11/18) | D49: 12/11/2018 - Dec 2018 | E49: 2019 | F49: 2020 | G49: 2021 | H49: 2022 | I49: 2023 | J49: 2024 | K49: stoves add/cumul
B50: (1st y effective operational stoves) | E50: =8000-D51+12000*10.5/12+18000*7.5/12+24000*4.5/12+36000*1.5/12 -> 40750 | F50: =F51/2 -> 121500 | G50: =G51/2 -> 60750 | L50: ECOEYE | M50: KOREA ZINC | N50: Total | O50: Expected Schedule
B51: (whole year add. stoves) | C51: 13000 | D51: 2500 | E51: =8000-D51+12000+18000+24000+36000 -> 95500 | F51: =40500*6 -> 243000 | G51: =3*40500 -> 121500 | L51: ERs | M51: ERs | N51: ERs | O51: CER Issuance | P51: KOC Issuance
B52: Effective Nb of stoves CPA1 | C52: 12977 | D52: 8016 | E52: 38128
B53: Effective Nb of stoves CPA2 | C53: 0 | D53: 0 | E53: 51624
B54: Total Nb of stoves | C54: =C52+C53 -> 12977 | D54: =D52+D53 -> 8016 | E54: =E52+E53 -> 89752 | F54: =F52+F53 -> 0
A55: MP1 | B55: 30/11/2018 - 14/12/2018 | C55: 563 | D55: 90 | E55: 0 | F55: 0
...

Sheet sample size CPA1
I2: Oversampling | J2: 0.2
B4: 2018 Batch
A5: Parameters | B5: Description | C5: level of confidence/precision | D5: z - values | E5: Size of the population of stoves considered for the monitoring session | F5: Expected proportion (p) | I5: Sample size before oversampling | J5: Sample size after oversampling | N5: batch | O5: population | P5: sample size | Q5: Oversampled size | R5: Final number of surveys conducted | S5: required purchase date
A6: pop stoves,y | B6: Proportion of distributed ICS still operating or replaced by an equivalent in service appliance under similar conditions under the project activity in year y | C6: 90 / 10 | D6: 1.645 | E6: ='Database - main figures'!B9 -> 35142 | F6: 0.9 | I6: =ROUNDUP((D6*D6*E6*F6*(1-F6))/(((E6-1)*0.1*0.1*F6*F6)+D6*D6*F6*(1-F6)),0) -> 31 | J6: =ROUNDUP(I6+I6*$J$2,0) -> 38 | N6: 2018 | O6: =E6 -> 35142 | P6: =I8 -> 48 | Q6: =J8 -> 58 | R6: =+'MP5 Monitoring surveys'!D216 -> 67 | S6: 04/06/2018 - 03/06/2019
C7: 95 / 10 | D7: 1.96 | E7: - | F7: - | I7: - | J7: - | N7: 2019 | O7: =E16 -> 69872 | P7: =I18 -> 48 | Q7: =J18 -> 58 | R7: =+'MP5 Monitoring surveys'!D217 -> 73 | S7: 04/06/2019 - 03/06/2020
A8: µ,y (pre-project devices use) | B8: Proportion of residual use of woody biomass from non-renewable sources under the project activity in year y | C8: 90 / 10 | D8: 1.645 | E8: ='Database - main figures'!B9 -> 35142 | F8: 0.85 | I8: =ROUNDUP((D8*D8*E8*F8*(1-F8))/(((E8-1)*0.1*0.1*F8*F8)+10*D8*F8*(1-F8)),0) -> 48 | J8: =ROUNDUP(I8+I8*$J$2,0) -> 58 | N8: 2020 | O8: =E26 -> 98446 | P8: =I28 -> 48 | Q8: =J28 -> 58 | R8: =+'MP5 Monitoring surveys'!D218 -> 70 | S8: 04/06/2020 - 03/06/2021
C9: 95 / 10 | D9: 1.96 | E9: =E7 -> - | F9: - | I9: - | J9: - | N9: Total | O9: =SUM(O6:O8) -> 203460 | P9: =SUM(P6:P8) -> 144 | Q9: =SUM(Q6:Q8) -> 174 | R9: =SUM(R6:R8) -> 210
B10: Description | C10: level of confidence/precision | D10: z - values | E10: Size of the population of stoves considered for the monitoring session | F10: Standard Deviation and Mean | G10: Equation for V | H10: V
A11: ηnew,y | B11: Efficiency of the device being deployed as part of the project activity in year y | C11: 90 / 10 | D11: 1.645 | E11: =E6 -> 35142 | F11: 0.01477 | H11: =(F11/F12)*(F11/F12) -> 0.0020923046 | I11: =ROUNDUP((D11*D11*E11*H11)/(((E11-1)*0.1*0.1+D11*D11*H11)),0) -> 1 | J11: =ROUNDUP(I11+I11*$J$2,0) -> 2
C12: 95 / 10 | F12: 0.3229
B14: 2019 Batch
A15: Parameters | B15: Description | C15: level of confidence/precision | D15: z - values | E15: Size of the population of stoves considered for the monitoring session | F15: Expected proportion (p) | I15: Sample size before oversampling | J15: Sample size after oversampling
A16: pop stoves,y | B16: Proportion of distributed ICS still operating or replaced by an equivalent in service appliance under similar conditions under the project activity in year y | C16: 90 / 10 | D16: 1.645 | E16: ='Database - main figures'!B10 -> 69872 | F16: 0.9 | I16: =ROUNDUP((D16*D16*E16*F16*(1-F16))/(((E16-1)*0.1*0.1*F16*F16)+D16*D16*F16*(1-F16)),0) -> 31 | J16: =ROUNDUP(I16+I16*$J$2,0) -> 38
C17: 95 / 10 | D17: 1.96 | E17: - | F17: - | I17: - | J17: -
A18: µ,y (pre-project devices use) | B18: Proportion of residual use of woody biomass from non-renewable sources under the project activity in year y | C18: 90 / 10 | D18: 1.645 | E18: ='Database - main figures'!B10 -> 69872 | F18: 0.85 | I18: =ROUNDUP((D18*D18*E18*F18*(1-F18))/(((E18-1)*0.1*0.1*F18*F18)+D18*D18*F18*(1-F18)),0) -> 48 | J18: =ROUNDUP(I18+I18*$J$2,0) -> 58
C19: 95 / 10 | D19: 1.96 | E19: =E17 -> - | F19: - | I19: - | J19: -
B20: Description | C20: level of confidence/precision | D20: z - values | E20: Size of the population of stoves considered for the monitoring session | F20: Standard Deviation and Mean | G20: Equation for V | H20: V
A21: ηnew,y | B21: Efficiency of the device being deployed as part of the project activity in year y | C21: 90 / 10 | D21: 1.645 | E21: =E16 -> 69872 | F21: 0.01477 | H21: =(F21/F22)*(F21/F22) -> 0.0020923046 | I21: =ROUNDUP((D21*D21*E21*H21)/(((E21-1)*0.1*0.1+D21*D21*H21)),0) -> 1 | J21: =ROUNDUP(I21+I21*$J$2,0) -> 2
C22: 95 / 10 | D22: 1.96 | E22: - | F22: 0.3229 | I22: - | J22: -
B24: 2020 Batch
A25: Parameters | B25: Description | C25: level of confidence/precision | D25: z - values | E25: Size of the population of stoves considered for the monitoring session | F25: Expected proportion (p) | I25: Sample size before oversampling | J25: Sample size after oversampling
A26: pop stoves,y | B26: Proportion of distributed ICS still operating or replaced by an equivalent in service appliance under similar conditions under the project activity in year y | C26: 90 / 10 | D26: 1.645 | E26: ='Database - main figures'!B11 -> 98446 | F26: 0.9 | I26: =ROUNDUP((D26*D26*E26*F26*(1-F26))/(((E26-1)*0.1*0.1*F26*F26)+D26*D26*F26*(1-F26)),0) -> 31 | J26: =ROUNDUP(I26+I26*$J$2,0) -> 38
C27: 95 / 10 | D27: 1.96 | E27: - | F27: - | I27: - | J27: -
A28: µ,y (pre-project devices use) | B28: Proportion of residual use of woody biomass from non-renewable sources under the project activity in year y | C28: 90 / 10 | D28: 1.645 | E28: =E26 -> 98446 | F28: 0.85 | I28: =ROUNDUP((D28*D28*E28*F28*(1-F28))/(((E28-1)*0.1*0.1*F28*F28)+D28*D28*F28*(1-F28)),0) -> 48 | J28: =ROUNDUP(I28+I28*$J$2,0) -> 58 | M28: =J28*3 -> 174
C29: 95 / 10 | D29: 1.96 | E29: - | F29: - | I29: - | J29: -
B30: Description | C30: level of confidence/precision | D30: z - values | E30: Size of the population of stoves considered for the monitoring session | F30: Standard Deviation and Mean | G30: Equation for V | H30: V
A31: ηnew,y | B31: Efficiency of the device being deployed as part of the project activity in year y | C31: 90 / 10 | D31: 1.645 | E31: =E26 -> 98446 | F31: 0.01477 | H31: =(F31/F32)*(F31/F32) -> 0.0020923046 | I31: =ROUNDUP((D31*D31*E31*H31)/(((E31-1)*0.1*0.1+D31*D31*H31)),0) -> 1 | J31: =ROUNDUP(I31+I31*$J$2,0) -> 2
F32: 0.3229
A34: E | B34: Achieved relative precision at given confidence level of 90% | C34: =SQRT(((D11^2*E11*(F11/F12)^2)/I11-D11^2*(F11/F12)^2)/(E11-1)) -> 0.075245122
D36: t (α/2) Student t Critical Values | E36: Size of the population of stoves considered for the monitoring session | F36: Standard Deviation and Mean | G36: s2 | H36: SE | I36: Sample size before oversampling | J36: E
A37: E | B37: Achieved relative precision at given confidence level (p.94 Sampling Guideline) | C37: 90 / 10 | D37: =TINV(0.1,J11-1) -> 6.3137515 | E37: ='Database - main figures'!B8 -> 203460 | F37: =F11 -> 0.01477 | G37: =F37*F37 -> 0.0002181529 | H37: =SQRT(((1-I37/E37)*G37)/I37) -> 0.014769964 | I37: =ROUNDUP((D37*D37*E37*G37)/(((E37-1)*0.1*0.1+D37*D37*G37)),0) -> 1 | J37: =D37*H37/F38 -> 0.28880112
F38: =F12 -> 0.3229
A41: Where:
A42: E | B42: Relative precision (e.g. 0.1 for 10% precision) | H42: Where:
A43: t | B43: t value | H43: SE | I43: Standard error
A44: SE | B44: Standard error | H44: f | I44: sampling fraction (n/N)
H45: n | I45: Sample size
A46: p.94, sampling guidelines | H46: s² | I46: variance (square root of SD)
A47: (The ratio of the relative precision E to the mean reveals the precision value.) | H47: t | I47: t value
H49: p.94, sampling guidelines

Sheet Ex-Ante Comparaison
D2: Nb of days | E2: EX ANTE Reduction | G2: REGISTERED VALUES
A3: CPA1 | B3: CPA Start Date | C3: 43448 | D3: =H3-C3+1 -> 18 | G3: 43431 | H3: 43465 | I3: 2213
B4: CPA End Date | C4: 43812 | D4: =C4-G4+1 -> 347 | G4: 43466 | H4: 43830 | I4: 78390
B5: CPA Start Date | C5: ='VCU calculation'!C6 -> 44713 | D5: =H4+1-C5 -> -882 | G5: 43831 | H5: 44196 | I5: 242969
B6: CPA End Date | C6: ='VCU calculation'!D6 -> 44926
B7: Nb of 2018 days
B8: Nb of 2019 days | C8: =H4-C5+1 -> -882 | E8: =C8*I4/365 -> -189424.6
B9: Nb of 2020 days | C9: =C6-G5+1 -> 1096 | E9: =C9*I5/366 -> 727579.3
B10: Total Ex ante | E10: =E8+E9+E7 -> 538154.7
E12: EX ANTE Reduction
A13: CPA2 | B13: CPA Start Date | C13: 43626 | D13: =C14+1-C13 -> 187 | G13: REGISTERED VALUES
B14: CPA End Date | C14: 43812 | G14: 43617 | H14: 43830 | I14: 21016
B15: CPA Start Date | C15: =C5 -> 44713 | D15: =H14+1-C15 -> -882 | G15: 43831 | H15: 44196 | I15: 125948
B16: CPA End Date | C16: =C6 -> 44926 | D16: =C16+1-G15 -> 1096
B17: Nb of 2019 days | C17: =H14-C15+1 -> -882 | E17: =C17*I14/214 -> -86617.346
B18: Nb of 2020 days | C18: =D16 -> 1096 | E18: =C18*I15/366 -> 377155.76
B19: Total Ex ante | E19: =E17+E18 -> 290538.41
B22: TOTAL EX ANTE | E22: =E19+E10 -> 828693.11

Sheet MP5 Monitoring surveys
A1: survey date | B1: surveyor name | C1: Name | D1: stove ID | E1: number of people in the household | F1: Adress | G1: telephone number | H1: Purchase date | I1: stove used recently ? | J1: stove working ? | K1: Number of Man&Man stove | L1: Other stove? | M1: if yes, type | N1: M&M frequency per day | O1: other stove frequency per day | P1: Uy | Q1: was this stove sampled for testing ? | R1: Less smoke ? | S1: Money savings? | T1: Grievance or comments? | U1: Batch | W1: 43255 | X1: 43620 | Y1: 43986
A2: 44932 | B2: Raphael Agyei Sarkodie | C2: Sakina Yaya | D2: cdm13649 | E2: 12 | F2: Techiman | G2: 0245437171 | H2: 43430 | I2: yes | J2: yes | K2: 2 | L2: no | N2: 3 | O2: 0 | P2: =O2/(O2+N2) -> 0 | Q2: no | R2: yes | S2: yes | T2: - | U2: =IF(AND(H2>=$W$1,H2<$X$1),"2018",IF(AND(H2>=$X$1,H2<$Y$1),"2019",IF(H2>=$Y$1,"2020"))) -> 2018
A3: 44940 | B3: Ibrahim Alhassan | C3: Juana Boatemaa | D3: cdm12461 | E3: 10 | F3: Berekum Kato | G3: 0541522637 | H3: 43405 | I3: no | J3: no | K3: 1 | L3: yes | M3: Three stone cooking fire | N3: 0 | O3: 1 | P3: =O3/(O3+N3) -> 1 | Q3: no | R3: no | S3: no | T3: Stove replacement for end user | U3: =IF(AND(H3>=$W$1,H3<$X$1),"2018",IF(AND(H3>=$X$1,H3<$Y$1),"2019",IF(H3>=$Y$1,"2020"))) -> 2018
A4: 44942 | B4: Ibrahim Alhassan | C4: Mary Krumah Ama | D4: cdm17187 | E4: 6 | F4: Berekum | G4: 0599976912 | H4: 43440 | I4: yes | J4: yes | K4: 1 | L4: no | N4: 3 | O4: 0 | P4: =O4/(O4+N4) -> 0 | Q4: no | R4: yes | S4: yes | T4: - | U4: =IF(AND(H4>=$W$1,H4<$X$1),"2018",IF(AND(H4>=$X$1,H4<$Y$1),"2019",IF(H4>=$Y$1,"2020"))) -> 2018
A5: 44943 | B5: Nicholas Frimpong | C5: Grace Amele | D5: cdm19100 | E5: 6 | F5: Yawhima | G5: 0591711153 | H5: 43458 | I5: yes | J5: yes | K5: 1 | L5: no | N5: 3 | O5: 0 | P5: =O5/(O5+N5) -> 0 | Q5: no | R5: yes | S5: yes | T5: - | U5: =IF(AND(H5>=$W$1,H5<$X$1),"2018",IF(AND(H5>=$X$1,H5<$Y$1),"2019",IF(H5>=$Y$1,"2020"))) -> 2018
A6: 44943 | B6: Mahama Mohammed | C6: Lucy Amoah | D6: cdm17777 | E6: 6 | F6: Odumasi | G6: 0277579462 | H6: 43456 | I6: yes | J6: yes | K6: 1 | L6: yes | M6: Three stone cooking fire | N6: 3 | O6: =1/7 -> 0.14285714 | P6: =O6/(O6+N6) -> 0.045454545 | Q6: no | R6: yes | S6: yes | T6: - | U6: =IF(AND(H6>=$W$1,H6<$X$1),"2018",IF(AND(H6>=$X$1,H6<$Y$1),"2019",IF(H6>=$Y$1,"2020"))) -> 2018
A7: 44938 | B7: Raphael Agyei Sarkodie | C7: Asana Seidu | D7: cdm23567 | E7: 7 | F7: sunyani Chiraa | G7: 0547705303 | H7: 43458 | I7: yes | J7: yes | K7: 1 | L7: yes | M7: Traditional coal pot/ Three stone cooking fires | N7: 2 | O7: =1.1 -> 1.1 | P7: =O7/(O7+N7) -> 0.35483871 | Q7: no | R7: yes | S7: yes | T7: - | U7: =IF(AND(H7>=$W$1,H7<$X$1),"2018",IF(AND(H7>=$X$1,H7<$Y$1),"2019",IF(H7>=$Y$1,"2020"))) -> 2018
A8: 44940 | B8: Nicholas Frimpong | C8: Yaa Afrakoma | D8: cdm19232 | E8: 4 | F8: Berekum Kato | G8: 0542094188 | H8: 43447 | I8: yes | J8: yes | K8: 1 | L8: yes | M8: Traditional coal pot/ Three stone cooking fires | N8: 2 | O8: =1.2 -> 1.2 | P8: =O8/(O8+N8) -> 0.375 | Q8: no | R8: yes | S8: yes | T8: Sheet beneath stove not strong | U8: =IF(AND(H8>=$W$1,H8<$X$1),"2018",IF(AND(H8>=$X$1,H8<$Y$1),"2019",IF(H8>=$Y$1,"2020"))) -> 2018
A9: 44937 | B9: Ibrahim Alhassan | C9: Yaa Owusuwaa | D9: cdm20416 | E9: 6 | F9: Fiapre | G9: 0556265181 | H9: 43457 | I9: yes | J9: yes | K9: 2 | L9: yes | M9: There stone cooking fires | N9: 3 | O9: 2 | P9: =O9/(O9+N9) -> 0.4 | Q9: no | R9: yes | S9: yes | T9: - | U9: =IF(AND(H9>=$W$1,H9<$X$1),"2018",IF(AND(H9>=$X$1,H9<$Y$1),"2019",IF(H9>=$Y$1,"2020"))) -> 2018
A10: 44942 | B10: Mahama Mohamamed | C10: Agyeiwaa Martha | D10: cdm6770 | E10: 5 | F10: Berekum | G10: 0246468747 | H10: 43335 | I10: yes | J10: yes | K10: 1 | L10: yes | M10: Traditional coal pot | N10: 3 | O10: =2/7 -> 0.28571429 | P10: =O10/(O10+N10) -> 0.086956522 | Q10: no | R10: yes | S10: yes | T10: - | U10: =IF(AND(H10>=$W$1,H10<$X$1),"2018",IF(AND(H10>=$X$1,H10<$Y$1),"2019",IF(H10>=$Y$1,"2020"))) -> 2018
A11: 44930 | B11: Mahama Mohamamed | C11: Karim Sata | D11: cdm4875 | E11: 6 | F11: Sunyani new Dormaa | G11: 0550962443 | H11: 43370 | I11: yes | J11: yes | K11: 1 | L11: yes | M11: Gas stove | N11: 2 | O11: 1 | P11: =O11/(O11+N11) -> 0.33333333 | Q11: no | R11: yes | S11: yes | T11: Functions well | U11: =IF(AND(H11>=$W$1,H11<$X$1),"2018",IF(AND(H11>=$X$1,H11<$Y$1),"2019",IF(H11>=$Y$1,"2020"))) -> 2018
A12: 44931 | B12: Ibrahim Alhassan | C12: Fatemata | D12: cdm32483 | E12: 20 | F12: Sunyani | G12: 0543220137 | H12: 43549 | I12: no | J12: no | K12: 1 | L12: yes | M12: Traditional coal pot/Three stone cooking fires | N12: 0 | O12: =1+ 0.1 -> 1.1 | P12: =O12/(O12+N12) -> 1 | Q12: no | R12: no | S12: no | T12: Stove replacement for primary cook | U12: =IF(AND(H12>=$W$1,H12<$X$1),"2018",IF(AND(H12>=$X$1,H12<$Y$1),"2019",IF(H12>=$Y$1,"2020"))) -> 2018
A13: 44942 | B13: Nicholas Frimpong | C13: Yeboah Martha | D13: cdm9123 | E13: 6 | F13: Berekum | G13: 0206431566 | H13: 43349 | I13: yes | J13: yes | K13: 1 | L13: yes | M13: Gas stove | N13: 2 | O13: 1 | P13: =O13/(O13+N13) -> 0.33333333 | Q13: no | R13: yes | S13: yes | T13: Works well | U13: =IF(AND(H13>=$W$1,H13<$X$1),"2018",IF(AND(H13>=$X$1,H13<$Y$1),"2019",IF(H13>=$Y$1,"2020"))) -> 2018
A14: 44928 | B14: Raphael Agyei Sarkodie | C14: Yaa Kosei | D14: cdm6032 | E14: 8 | F14: Sunyani Zongo | G14: 0550328808 | H14: 43341 | I14: yes | J14: yes | K14: 1 | L14: yes | M14: Traditional coal pot | N14: 3 | O14: =1/7 -> 0.14285714 | P14: =O14/(O14+N14) -> 0.045454545 | Q14: no | R14: yes | S14: yes | T14: - | U14: =IF(AND(H14>=$W$1,H14<$X$1),"2018",IF(AND(H14>=$X$1,H14<$Y$1),"2019",IF(H14>=$Y$1,"2020"))) -> 2018
A15: 44933 | B15: Ibrahim Alhassan | C15: Alima Abdalla | D15: cdm6277 | E15: 3 | F15: Wenchi | G15: 0243182041 | H15: 43334 | I15: yes | J15: yes | K15: 1 | L15: yes | M15: Traditional coal pot, Three stone cooking fires | N15: 2 | O15: =1+0.1 -> 1.1 | P15: =O15/(O15+N15) -> 0.35483871 | Q15: no | R15: yes | S15: yes | T15: - | U15: =IF(AND(H15>=$W$1,H15<$X$1),"2018",IF(AND(H15>=$X$1,H15<$Y$1),"2019",IF(H15>=$Y$1,"2020"))) -> 2018
A16: 44937 | B16: Raphael Agyei Sarkodie | C16: Ataa Yaa | D16: cdm1253 | E16: 7 | F16: Fiapre | G16: 0203716300 | H16: 43284 | I16: no | J16: no | K16: 1 | L16: yes | M16: Traditional coal pot, gas stove | N16: 0 | O16: =1+0.3 -> 1.3 | P16: =O16/(O16+N16) -> 1 | Q16: no | R16: no | S16: no | T16: Stove replacement for primary cook | U16: =IF(AND(H16>=$W$1,H16<$X$1),"2018",IF(AND(H16>=$X$1,H16<$Y$1),"2019",IF(H16>=$Y$1,"2020"))) -> 2018
A17: 44928 | B17: Nicholas Frimpong | C17: Constance Gyan | D17: cdm1444 | E17: 6 | F17: Sunyani Nkwabeng South | G17: 0505016968 | H17: 43287 | I17: yes | J17: yes | K17: 1 | L17: no | N17: 2 | O17: 0 | P17: =O17/(O17+N17) -> 0 | Q17: no | R17: yes | S17: yes | T17: - | U17: =IF(AND(H17>=$W$1,H17<$X$1),"2018",IF(AND(H17>=$X$1,H17<$Y$1),"2019",IF(H17>=$Y$1,"2020"))) -> 2018
A18: 44929 | B18: Nicholas Frimpong | C18: Janet Henewaa | D18: cdm2007 | E18: 2 | F18: Sunyani Newtown | G18: 0546660674 | H18: 43293 | I18: yes | J18: yes | K18: 1 | L18: yes | M18: Traditional coal pot | N18: 2 | O18: 1 | P18: =O18/(O18+N18) -> 0.33333333 | Q18: no | R18: yes | S18: yes | T18: - | U18: =IF(AND(H18>=$W$1,H18<$X$1),"2018",IF(AND(H18>=$X$1,H18<$Y$1),"2019",IF(H18>=$Y$1,"2020"))) -> 2018
A19: 44928 | B19: Ibrahim Alhassan | C19: Adiza Isaka | D19: cdm91 | E19: 7 | F19: Sunyani Nkwabeng | G19: 0596887071 | H19: 43285 | I19: yes | J19: yes | K19: 1 | L19: no | N19: 3 | O19: 0 | P19: =O19/(O19+N19) -> 0 | Q19: no | R19: yes | S19: yes | T19: - | U19: =IF(AND(H19>=$W$1,H19<$X$1),"2018",IF(AND(H19>=$X$1,H19<$Y$1),"2019",IF(H19>=$Y$1,"2020"))) -> 2018
A20: 44929 | B20: Mahama Mohamamed | C20: Elizabeth Mansah | D20: cdm2003 | E20: 4 | F20: Sunyani Newtown | G20: 0553291773 | H20: 43288 | I20: yes | J20: yes | K20: 1 | L20: no | N20: 2 | O20: 0 | P20: =O20/(O20+N20) -> 0 | Q20: no | R20: yes | S20: yes | T20: - | U20: =IF(AND(H20>=$W$1,H20<$X$1),"2018",IF(AND(H20>=$X$1,H20<$Y$1),"2019",IF(H20>=$Y$1,"2020"))) -> 2018
A21: 44942 | B21: Nicholas Frimpong | C21: Owusuwaa Diana | D21: cdm2938 | E21: 5 | F21: Berekum | G21: 0209745539 | H21: 43298 | I21: yes | J21: yes | K21: 1 | L21: no | N21: 2 | O21: 0 | P21: =O21/(O21+N21) -> 0 | Q21: no | R21: yes | S21: yes | T21: - | U21: =IF(AND(H21>=$W$1,H21<$X$1),"2018",IF(AND(H21>=$X$1,H21<$Y$1),"2019",IF(H21>=$Y$1,"2020"))) -> 2018
A22: 44931 | B22: Raphael Agyei Sarkodie | C22: Forson Susuna Esi | D22: cdm1463 | E22: 4 | F22: Sunyani Area 4 | G22: 0209129388 | H22: 43293 | I22: yes | J22: yes | K22: 1 | L22: no | N22: 2 | O22: 0 | P22: =O22/(O22+N22) -> 0 | Q22: no | R22: yes | S22: yes | T22: - | U22: =IF(AND(H22>=$W$1,H22<$X$1),"2018",IF(AND(H22>=$X$1,H22<$Y$1),"2019",IF(H22>=$Y$1,"2020"))) -> 2018
A23: 44931 | B23: Ibrahim Alhassan | C23: Lydia Tetteh | D23: cdm2084 | E23: 3 | F23: Sunyani Area 4 | G23: 0559281996 | H23: 43293 | I23: yes | J23: yes | K23: 1 | L23: yes | M23: Traditional coal pot | N23: 2 | O23: 1 | P23: =O23/(O23+N23) -> 0.33333333 | Q23: no | R23: yes | S23: yes | T23: - | U23: =IF(AND(H23>=$W$1,H23<$X$1),"2018",IF(AND(H23>=$X$1,H23<$Y$1),"2019",IF(H23>=$Y$1,"2020"))) -> 2018
A24: 44938 | B24: Nicholas Frimpong | C24: Sister Theresah | D24: cdm3130 | E24: 12 | F24: Chiraa | G24: 0540982503 | H24: 43291 | I24: no | J24: no | K24: 1 | L24: yes | M24: Gas stove | N24: 0 | O24: =1/7 -> 0.14285714 | P24: =O24/(O24+N24) -> 1 | Q24: no | R24: no | S24: no | T24: Stove replacement for end user | U24: =IF(AND(H24>=$W$1,H24<$X$1),"2018",IF(AND(H24>=$X$1,H24<$Y$1),"2019",IF(H24>=$Y$1,"2020"))) -> 2018
A25: 44942 | B25: Mahama Mohamamed | C25: Fuseina Duada | D25: cdm31082 | E25: 3 | F25: Berekum | G25: 0207484996 | H25: 43531 | I25: yes | J25: yes | K25: 1 | L25: yes | M25: Three stone cooking fires | N25: 2 | O25: 1 | P25: =O25/(O25+N25) -> 0.33333333 | Q25: no | R25: yes | S25: yes | T25: - | U25: =IF(AND(H25>=$W$1,H25<$X$1),"2018",IF(AND(H25>=$X$1,H25<$Y$1),"2019",IF(H25>=$Y$1,"2020"))) -> 2018
A26: 44942 | B26: Mahama Mohamamed | C26: Janet Febiri | D26: cdm27561 | E26: 8 | F26: Berekum Kato | G26: 0241169387 | H26: 43510 | I26: yes | J26: yes | K26: 1 | L26: yes | M26: traditional coal pot/gas stove | N26: 3 | O26: =0.1+0.1 -> 0.2 | P26: =O26/(O26+N26) -> 0.0625 | Q26: no | R26: yes | S26: yes | T26: - | U26: =IF(AND(H26>=$W$1,H26<$X$1),"2018",IF(AND(H26>=$X$1,H26<$Y$1),"2019",IF(H26>=$Y$1,"2020"))) -> 2018
A27: 44942 | B27: Raphael Agyei Sarkodie | C27: Georgina Kyeraa | D27: cdm27031 | E27: 6 | F27: Berekum Jinijini | G27: 0243246128 | H27: 43503 | I27: yes | J27: yes | K27: 1 | L27: yes | M27: Traditional coal pot | N27: 2 | O27: 1 | P27: =O27/(O27+N27) -> 0.33333333 | Q27: no | R27: yes | S27: yes | T27: - | U27: =IF(AND(H27>=$W$1,H27<$X$1),"2018",IF(AND(H27>=$X$1,H27<$Y$1),"2019",IF(H27>=$Y$1,"2020"))) -> 2018
A28: 44930 | B28: Ibrahim Alhassan | C28: Boateng Doris | D28: cdm11017 | E28: 4 | F28: Penkwase | G28: 0244795372 | H28: 43370 | I28: yes | J28: yes | K28: 1 | L28: yes | M28: Traditional coal pot | N28: 2 | O28: 1 | P28: =O28/(O28+N28) -> 0.33333333 | Q28: no | R28: yes | S28: yes | T28: - | U28: =IF(AND(H28>=$W$1,H28<$X$1),"2018",IF(AND(H28>=$X$1,H28<$Y$1),"2019",IF(H28>=$Y$1,"2020"))) -> 2018
A29: 44937 | B29: Ibrahim Alhassan | C29: Esther Anima | D29: cdm11493 | E29: 7 | F29: Fiapre | G29: 0203479138 | H29: 43395 | I29: no | J29: no | K29: 1 | L29: yes | M29: Gas stove | N29: 0 | O29: 1 | P29: =O29/(O29+N29) -> 1 | Q29: no | R29: no | S29: no | T29: Stove replacement for end user | U29: =IF(AND(H29>=$W$1,H29<$X$1),"2018",IF(AND(H29>=$X$1,H29<$Y$1),"2019",IF(H29>=$Y$1,"2020"))) -> 2018
A30: 44930 | B30: Nicholas Frimpong | C30: Kumson Dora | D30: cdm6740 | E30: 5 | F30: Penkwase | G30: 0554593057 | H30: 43346 | I30: yes | J30: yes | K30: 1 | L30: yes | M30: traditional coal pot | N30: 3 | O30: 1 | P30: =O30/(O30+N30) -> 0.25 | Q30: no | R30: yes | S30: yes | T30: - | U30: =IF(AND(H30>=$W$1,H30<$X$1),"2018",IF(AND(H30>=$X$1,H30<$Y$1),"2019",IF(H30>=$Y$1,"2020"))) -> 2018
A31: 44939 | B31: Ibrahim Alhassan | C31: Beatrice Amankwah | D31: cdm43818 | E31: 4 | F31: Abesim | G31: 0544253653 | H31: 43602 | I31: yes | J31: yes | K31: 1 | L31: no | N31: 2 | P31: =O31/(O31+N31) -> 0 | Q31: no | R31: yes | S31: yes | T31: - | U31: =IF(AND(H31>=$W$1,H31<$X$1),"2018",IF(AND(H31>=$X$1,H31<$Y$1),"2019",IF(H31>=$Y$1,"2020"))) -> 2018
A32: 44932 | B32: Raphael Agyei Sarkodie | C32: Cecilia Kyeremaa | D32: cdm39375 | E32: 4 | F32: Techiman Wangala line | G32: 0556074079 | H32: 43593 | I32: yes | J32: yes | K32: 1 | L32: yes | M32: traditional coal pot | N32: 3 | O32: =1/7 -> 0.14285714 | P32: =O32/(O32+N32) -> 0.045454545 | Q32: no | R32: yes | S32: yes | T32: - | U32: =IF(AND(H32>=$W$1,H32<$X$1),"2018",IF(AND(H32>=$X$1,H32<$Y$1),"2019",IF(H32>=$Y$1,"2020"))) -> 2018
A33: 44946 | B33: Raphael Agyei Sarkodie | C33: Rafiah Mohammed | D33: cdm43026 | E33: 6 | F33: Techiman dagomba line | G33: 0592583192 | H33: 43601 | I33: yes | J33: yes | K33: 1 | L33: yes | M33: traditional coal pot | N33: 3 | O33: =1/7 -> 0.14285714 | P33: =O33/(O33+N33) -> 0.045454545 | Q33: no | R33: yes | S33: yes | T33: - | U33: =IF(AND(H33>=$W$1,H33<$X$1),"2018",IF(AND(H33>=$X$1,H33<$Y$1),"2019",IF(H33>=$Y$1,"2020"))) -> 2018
A34: 44943 | B34: Raphael Agyei Sarkodie | C34: Fati Moro | D34: cdm43935 | E34: 7 | F34: Yawhima | G34: 0248476372 | H34: 43647 | I34: yes | J34: yes | K34: 2 | L34: yes | M34: Three stone cooking fires | N34: 3 | O34: 2 | P34: =O34/(O34+N34) -> 0.4 | Q34: no | R34: yes | S34: yes | T34: - | U34: =IF(AND(H34>=$W$1,H34<$X$1),"2018",IF(AND(H34>=$X$1,H34<$Y$1),"2019",IF(H34>=$Y$1,"2020"))) -> 2019
A35: 44938 | B35: Nicholas Frimpong | C35: Kumi Annah | D35: 2m4971 | E35: 3 | F35: sunyani Chiraa | G35: 0247155524 | H35: 43774 | I35: yes | J35: yes | K35: 1 | L35: no | N35: 3 | P35: =O35/(O35+N35) -> 0 | Q35: no | R35: yes | S35: yes | T35: - | U35: =IF(AND(H35>=$W$1,H35<$X$1),"2018",IF(AND(H35>=$X$1,H35<$Y$1),"2019",IF(H35>=$Y$1,"2020"))) -> 2019
A36: 44940 | B36: Nicholas Frimpong | C36: Comfort Nyarko | D36: cdm26228 | E36: 8 | F36: Berekum Kato | G36: 0208713961 | H36: 43510 | I36: yes | J36: yes | K36: 1 | L36: yes | M36: Gas stove | N36: 2 | O36: =1/7 -> 0.14285714 | P36: =O36/(O36+N36) -> 0.066666667 | Q36: no | R36: yes | S36: yes | T36: Handle of stove is weak | U36: =IF(AND(H36>=$W$1,H36<$X$1),"2018",IF(AND(H36>=$X$1,H36<$Y$1),"2019",IF(H36>=$Y$1,"2020"))) -> 2018
A37: 44933 | B37: Raphael Agyei Sarkodie | C37: Mary Vivian | D37: cdm43317 | E37: 5 | F37: Wenchi Zongo | G37: 0246031939 | H37: 43601 | I37: yes | J37: yes | K37: 1 | L37: yes | M37: Gas stove | N37: 2 | O37: 1 | P37: =O37/(O37+N37) -> 0.33333333 | Q37: no | R37: yes | S37: yes | T37: - | U37: =IF(AND(H37>=$W$1,H37<$X$1),"2018",IF(AND(H37>=$X$1,H37<$Y$1),"2019",IF(H37>=$Y$1,"2020"))) -> 2018
A38: 44928 | B38: Nicholas Frimpong | C38: Boevi Janet | D38: cdm 17307 | E38: 6 | F38: Sunyani | G38: 0553579291 | H38: 43446 | I38: yes | J38: yes | K38: 2 | L38: no | N38: 3 | P38: =O38/(O38+N38) -> 0 | Q38: no | R38: yes | S38: yes | T38: - | U38: =IF(AND(H38>=$W$1,H38<$X$1),"2018",IF(AND(H38>=$X$1,H38<$Y$1),"2019",IF(H38>=$Y$1,"2020"))) -> 2018
A39: 44928 | B39: Nicholas Frimpong | C39: Adwoa Dufie | D39: cdm26486 | E39: 3 | F39: Sunyani | G39: 0246363081 | H39: 43490 | I39: yes | J39: yes | K39: 1 | L39: yes | M39: Gas stove | N39: 2 | O39: =2/7 -> 0.28571429 | P39: =O39/(O39+N39) -> 0.125 | Q39: no | R39: yes | S39: yes | T39: - | U39: =IF(AND(H39>=$W$1,H39<$X$1),"2018",IF(AND(H39>=$X$1,H39<$Y$1),"2019",IF(H39>=$Y$1,"2020"))) -> 2018
A40: 44943 | B40: Nicholas Frimpong | C40: Amina Constance | D40: cdm36143 | E40: 5 | F40: Yawhima | G40: 0596237826 | H40: 43599 | I40: yes | J40: yes | K40: 1 | L40: no | N40: 3 | P40: =O40/(O40+N40) -> 0 | Q40: no | R40: yes | S40: yes | T40: - | U40: =IF(AND(H40>=$W$1,H40<$X$1),"2018",IF(AND(H40>=$X$1,H40<$Y$1),"2019",IF(H40>=$Y$1,"2020"))) -> 2018
...

Sheet MP5 stoves efficiency 
A2: WBT number | B2: CPA1 2018 age-group | C2: efficiency % | D2: WBT number | E2: CPA1 2019 age-group | F2: efficiency % | G2: WBT number | H2: CPA1 2020 age-group | I2: efficiency %
B3: CDM41832 | C3: =B32 -> 0.31066667 | E3: =E27 -> 2M377 | F3: =E32 -> 0.29533333 | H3: =H27 -> 4M74584 | I3: =H32 -> 0.29233333
B4: =C27 -> CDM15512 | C4: =C32 -> 0.306 | E4: =F27 -> 2M12261 | F4: =F32 -> 0.29033333 | H4: =I27 -> 4M71506 | I4: =I32 -> 0.29466667
B5: =D27 -> CDM17473 | C5: =D32 -> 0.329 | E5: =G27 -> 2M7284 | F5: =G32 -> 0.29666667 | H5: =J27 -> 3M32758 | I5: =J32 -> 0.29666667
B6: CPA1 2018 Age group | E6: CPA1 2019 Age group | H6: CPA1 2020 Age group
B7: average efficiency | C7: =AVERAGE(C3:C5) -> 0.31522222 | E7: average efficiency | F7: =AVERAGE(F3:F5) -> 0.29411111 | H7: average efficiency | I7: =AVERAGE(I3:I5) -> 0.29455556
B8: Standard deviation | C8: =STDEVA(C3:C5) -> 0.012157912 | E8: Standard deviation | F8: =STDEVA(F3:F5) -> 0.0033388843 | H8: Standard deviation | I8: =STDEVA(I3:I5) -> 0.0021688024
B9: Sample size | C9: =COUNT(C3:C5) -> 3 | E9: Sample size | F9: =COUNT(F3:F5) -> 3 | H9: Sample size | I9: =COUNT(I3:I5) -> 3
B10: Total population size | C10: =E21 -> 35142 | E10: Total population size | F10: =E22 -> 69872 | H10: Total population size | I10: =E23 -> 98446
B11: Required precision | C11: 0.9 | E11: Required precision | F11: 0.9 | H11: Required precision | I11: 0.9
B12: t-value at 90% confidence | C12: =TINV(0.1,C9-1) -> 2.9199856 | E12: t-value at 90% confidence | F12: =TINV(0.1,F9-1) -> 2.9199856 | H12: t-value at 90% confidence | I12: =TINV(0.1,I9-1) -> 2.9199856
B13: Confidence interval (+/-) | C13: =C12*SQRT(1-(C9/C10))*(C8/SQRT(C9)) -> 0.020495595 | E13: Confidence interval (+/-) | F13: =F12*SQRT(1-(F9/F10))*(F8/SQRT(F9)) -> 0.0056287521 | H13: Confidence interval (+/-) | I13: =I12*SQRT(1-(I9/I10))*(I8/SQRT(I9)) -> 0.0036562294
B14: Lower bound of the interval | C14: =C7-C13 -> 0.29472663 | E14: Lower bound of the interval | F14: =F7-F13 -> 0.28848236 | H14: Lower bound of the interval | I14: =I7-I13 -> 0.29089933
B15: Higher bound of the interval | C15: =C7+C13 -> 0.33571782 | E15: Higher bound of the interval | F15: =F7+F13 -> 0.29973986 | H15: Higher bound of the interval | I15: =I7+I13 -> 0.29821178
B16: Maximum error (precision) | C16: 0.1 | E16: Maximum error (precision) | F16: 0.1 | H16: Maximum error (precision) | I16: 0.1
B17: Sample precision | C17: =(((C15-C14)/2)/C7)*100% -> 0.065019511 | E17: Sample precision | F17: =(((F15-F14)/2)/F7)*100% -> 0.019138182 | H17: Sample precision | I17: =(((I15-I14)/2)/I7)*100% -> 0.012412699
B18: Conclusion | C18: =IF(C17<C16,"Precision OK","Precision not reached") -> Precision OK | E18: Conclusion | F18: =IF(F17<F16,"Precision OK","Precision not reached") -> Precision OK | H18: Conclusion | I18: =IF(I17<I16,"Precision OK","Precision not reached") -> Precision OK
B20: Stoves' age | C20: Purchase year | E20: Number of stoves sold | F20: Efficiency | G20: Final
B21: 4th year | C21: 2018 | E21: ='Database - main figures'!B9 -> 35142 | F21: =C7 -> 0.31522222 | G21: 0.295
B22: 3rd year | C22: 2019 | E22: ='Database - main figures'!B10 -> 69872 | F22: =F7 -> 0.29411111 | G22: =F22 -> 0.29411111
B23: 2nd year | C23: 2020 | E23: ='Database - main figures'!B11 -> 98446 | F23: =I7 -> 0.29455556 | G23: =F23 -> 0.29455556
C24: CPA1 vintage-weighted efficiency | E24: =E21+E22+E23 -> 203460
B26: 2018 batch | E26: 2019 batch | H26: 2020 batch
B27: CDM41832 | C27: CDM15512 | D27: CDM17473 | E27: 2M377 | F27: 2M12261 | G27: 2M7284 | H27: 4M74584 | I27: 4M71506 | J27: 3M32758
B28: stove 2,1 result | C28: stove 5,1 result | D28: stove 6,1 result | E28: stove 1,1 result | F28: stove 3,1 result | G28: stove 9,1 result | H28: stove 4,1 result | I28: stove 7,1 result | J28: stove 8,1 result
A29: Test 1 | B29: 0.315 | C29: 0.324 | D29: 0.319 | E29: 0.3 | F29: 0.302 | G29: 0.298 | H29: 0.305 | I29: 0.312 | J29: 0.286
A30: Test 2 | B30: 0.298 | C30: 0.294 | D30: 0.327 | E30: 0.297 | F30: 0.296 | G30: 0.306 | H30: 0.294 | I30: 0.285 | J30: 0.313
A31: Test 3 | B31: 0.319 | C31: 0.3 | D31: 0.341 | E31: 0.289 | F31: 0.273 | G31: 0.286 | H31: 0.278 | I31: 0.287 | J31: 0.291
A32: Mean | B32: =AVERAGE(B29:B31) -> 0.31066667 | C32: =AVERAGE(C29:C31) -> 0.306 | D32: =AVERAGE(D29:D31) -> 0.329 | E32: =AVERAGE(E29:E31) -> 0.29533333 | F32: =AVERAGE(F29:F31) -> 0.29033333 | G32: =AVERAGE(G29:G31) -> 0.29666667 | H32: =AVERAGE(H29:H31) -> 0.29233333 | I32: =AVERAGE(I29:I31) -> 0.29466667 | J32: =AVERAGE(J29:J31) -> 0.29666667
A33: Standard deviation | B33: =STDEVA(B29:B31) -> 0.011150486 | C33: =STDEVA(C29:C31) -> 0.015874508 | D33: =STDEVA(D29:D31) -> 0.011135529 | E33: =STDEVA(E29:E31) -> 0.0056862407 | F33: =STDEVA(F29:F31) -> 0.01530795 | G33: =STDEVA(G29:G31) -> 0.010066446 | H33: =STDEVA(H29:H31) -> 0.013576941 | I33: =STDEVA(I29:I31) -> 0.015044379 | J33: =STDEVA(J29:J31) -> 0.014364308

Sheet Database - main figures
A1: Due to the heavy weight of the tabs listing the different users of the ICS, these databases appear in a separate Excel file. Here are the main figures resulting from the analysis of this database
A2: For every change on the database, these figures must be updated in the ER calculation file.
A3: Due to the heavy weight of the tabs listing the different users of the ICS, these databases appear in a separate Excel file. Here are the main figures resulting from the analysis of this database
A4: For every change on the database, these figures must be updated in the ER calculation file.
A6: CPA001:
A7: Parameter | B7: Value | C7: Unit
A8: Nb of stoves sold for this CPA | B8: =SUM(B9:B11) -> 203460 | C8: stoves
A9: Nb of 2018 stoves | B9: ='[1]Database - main figures'!$B$7 -> 35142 | C9: stoves
A10: Nb of 2019 stoves | B10: ='[1]Database - main figures'!$B$8 -> 69872 | C10: stoves
A11: Nb of 2020 stoves | B11: ='[1]Database - main figures'!$B$9 -> 98446 | C11: stoves
A12: Nb of 2021+ stoves | B12: 0 | C12: stoves
A13: Nb of household users, as per name & address/town | B13: 197241 | C13: household users
A14: Nd,HH | B14: =B8/B13 -> 1.03153 | C14: projects stoves/household
G15: WBTs from CPA1
F16: =C18 -> 2018-2019 | G16: 3
A17: First stove sales date: | C17: batches | D17: CPA1 pop | F17: =C19 -> 2019-2020 | G17: =3*D19/(SUM(D19+E20)) -> 3
A18: 43255 | B18: =A18+364 -> 43619 | C18: 2018-2019 | D18: =B9 -> 35142 | F18: =C20 -> 2020-2021 | G18: =3*D20/(SUM(D20+E21)) -> 3
A19: =B18+1 -> 43620 | B19: =A19+365 -> 43985 | C19: 2019-2020 | D19: =B10 -> 69872 | F19: total | G19: =ROUNDDOWN(SUM(G16:G18),0) -> 9
A20: =B19+1 -> 43986 | B20: =A20+364 -> 44350 | C20: 2020-2021 | D20: =B11 -> 98446
C21: Total | D21: =SUM(D18:D20) -> 203460
